<sdf version='1.6'>
  <model name='SDVUN3'>
    <link name='base_link'>
      <pose frame=''>0 0 0 0 -0 0</pose>
      <inertial>
        <pose frame=''>0 0 0.151169 0 -0 0</pose>
        <mass>13.004</mass>
        <inertia>
          <ixx>0.319184</ixx>
          <ixy>0.00147742</ixy>
          <ixz>0.000332216</ixz>
          <iyy>0.537812</iyy>
          <iyz>-0.000228097</iyz>
          <izz>0.375025</izz>
        </inertia>
      </inertial>
      <collision name='base_link_collision'>
        <pose frame=''>0 0 0.229 0 -0 0</pose>
        <geometry>
          <mesh>
            <scale>1 1 1</scale>
            <uri>model://sdvun_description/models/sdvun3/meshes/collision_space.dae</uri>
          </mesh>
        </geometry>
      </collision>
      <collision name='base_link_fixed_joint_lump__laser_link_collision_1'>
        <pose frame=''>0.280694 0 0.224334 0 -0 0</pose>
        <geometry>
          <box>
            <size>0.1 0.1 0.1</size>
          </box>
        </geometry>
        <surface>
          <contact>
            <ode/>
          </contact>
          <friction>
            <ode/>
          </friction>
        </surface>
      </collision>
      <visual name='base_link_visual'>
        <pose frame=''>0 0 0.151169 0 -0 0</pose>
        <geometry>
          <mesh>
            <scale>1 1 1</scale>
            <uri>model://sdvun_description/models/sdvun3/meshes/sdvun3.dae</uri>
          </mesh>
        </geometry>
      </visual>
      <velocity_decay/>
      <sensor name='imu' type='imu'>
        <always_on>1</always_on>
        <pose frame=''>0 0 0.169718 0 -0 0</pose>
      </sensor>
      <gravity>1</gravity>
      <velocity_decay/>
      <sensor name='laser' type='gpu_ray'>
        <visualize>1</visualize>
        <update_rate>50</update_rate>
        <ray>
          <scan>
            <horizontal>
              <samples>360</samples>
              <resolution>1</resolution>
              <min_angle>-1.5708</min_angle>
              <max_angle>1.5708</max_angle>
            </horizontal>
          </scan>
          <range>
            <min>0.1</min>
            <max>20</max>
            <resolution>0.01</resolution>
          </range>
          <noise>
            <type>gaussian</type>
            <mean>0</mean>
            <stddev>0.001</stddev>
          </noise>
        </ray>
        <plugin name='gazebo_ros_laser' filename='libgazebo_ros_gpu_laser.so'>
          <topicName>scan</topicName>
          <frameName>laser_link</frameName>
          <robotNamespace>/</robotNamespace>
        </plugin>
        <pose frame=''>0.280694 0 0.224334 0 -0 0</pose>
      </sensor>
    </link>
    <link name='back_left_wheel'>
      <pose frame=''>-0.15972 0.21685 0.075 0 1.5707 -1.5707</pose>
      <inertial>
        <pose frame=''>0 0 0 0 -0 0</pose>
        <mass>0.377</mass>
        <inertia>
          <ixx>0.0375</ixx>
          <ixy>0</ixy>
          <ixz>0</ixz>
          <iyy>0.0375</iyy>
          <iyz>0</iyz>
          <izz>0.015</izz>
        </inertia>
      </inertial>
      <collision name='back_left_wheel_collision'>
        <pose frame=''>0 0 0 0 -0 0</pose>
        <geometry>
          <cylinder>
            <length>0.0453</length>
            <radius>0.075</radius>
          </cylinder>
        </geometry>
      </collision>
      <visual name='back_left_wheel_visual'>
        <pose frame=''>0 0 0 0 -0 0</pose>
        <geometry>
          <mesh>
            <scale>1 1 1</scale>
            <uri>model://sdvun_description/models/sdvun3/meshes/wheel.dae</uri>
          </mesh>
        </geometry>
      </visual>
    </link>
    <joint name='back_left_wheel_joint' type='revolute'>
      <child>back_left_wheel</child>
      <parent>base_link</parent>
      <axis>
        <xyz>-9.6e-05 1 -9.6e-05</xyz>
        <limit>
          <lower>-1e+16</lower>
          <upper>1e+16</upper>
        </limit>
        <dynamics>
          <spring_reference>0</spring_reference>
          <spring_stiffness>0</spring_stiffness>
        </dynamics>
        <use_parent_model_frame>1</use_parent_model_frame>
      </axis>
    </joint>
    <link name='back_right_wheel'>
      <pose frame=''>-0.15972 -0.21685 0.075 0 1.5707 1.5707</pose>
      <inertial>
        <pose frame=''>0 0 0 0 -0 0</pose>
        <mass>0.377</mass>
        <inertia>
          <ixx>0.0375</ixx>
          <ixy>0</ixy>
          <ixz>0</ixz>
          <iyy>0.0375</iyy>
          <iyz>0</iyz>
          <izz>0.015</izz>
        </inertia>
      </inertial>
      <collision name='back_right_wheel_collision'>
        <pose frame=''>0 0 0 0 -0 0</pose>
        <geometry>
          <cylinder>
            <length>0.0453</length>
            <radius>0.075</radius>
          </cylinder>
        </geometry>
      </collision>
      <visual name='back_right_wheel_visual'>
        <pose frame=''>0 0 0 0 -0 0</pose>
        <geometry>
          <mesh>
            <scale>1 1 1</scale>
            <uri>model://sdvun_description/models/sdvun3/meshes/wheel.dae</uri>
          </mesh>
        </geometry>
      </visual>
    </link>
    <joint name='back_right_wheel_joint' type='revolute'>
      <child>back_right_wheel</child>
      <parent>base_link</parent>
      <axis>
        <xyz>9.6e-05 1 9.6e-05</xyz>
        <limit>
          <lower>-1e+16</lower>
          <upper>1e+16</upper>
        </limit>
        <dynamics>
          <spring_reference>0</spring_reference>
          <spring_stiffness>0</spring_stiffness>
        </dynamics>
        <use_parent_model_frame>1</use_parent_model_frame>
      </axis>
    </joint>
    <link name='front_left_wheel'>
      <pose frame=''>0.15972 0.21685 0.075 0 1.5707 -1.5707</pose>
      <inertial>
        <pose frame=''>0 0 0 0 -0 0</pose>
        <mass>0.377</mass>
        <inertia>
          <ixx>0.0375</ixx>
          <ixy>0</ixy>
          <ixz>0</ixz>
          <iyy>0.0375</iyy>
          <iyz>0</iyz>
          <izz>0.015</izz>
        </inertia>
      </inertial>
      <collision name='front_left_wheel_collision'>
        <pose frame=''>0 0 0 0 -0 0</pose>
        <geometry>
          <cylinder>
            <length>0.0453</length>
            <radius>0.075</radius>
          </cylinder>
        </geometry>
      </collision>
      <visual name='front_left_wheel_visual'>
        <pose frame=''>0 0 0 0 -0 0</pose>
        <geometry>
          <mesh>
            <scale>1 1 1</scale>
            <uri>model://sdvun_description/models/sdvun3/meshes/wheel.dae</uri>
          </mesh>
        </geometry>
      </visual>
    </link>
    <joint name='front_left_wheel_joint' type='revolute'>
      <child>front_left_wheel</child>
      <parent>base_link</parent>
      <axis>
        <xyz>-9.6e-05 1 -9.6e-05</xyz>
        <limit>
          <lower>-1e+16</lower>
          <upper>1e+16</upper>
        </limit>
        <dynamics>
          <spring_reference>0</spring_reference>
          <spring_stiffness>0</spring_stiffness>
        </dynamics>
        <use_parent_model_frame>1</use_parent_model_frame>
      </axis>
    </joint>
    <link name='front_right_wheel'>
      <pose frame=''>0.15972 -0.21685 0.075 0 1.5707 1.5707</pose>
      <inertial>
        <pose frame=''>0 0 0 0 -0 0</pose>
        <mass>0.377</mass>
        <inertia>
          <ixx>0.0375</ixx>
          <ixy>0</ixy>
          <ixz>0</ixz>
          <iyy>0.0375</iyy>
          <iyz>0</iyz>
          <izz>0.015</izz>
        </inertia>
      </inertial>
      <collision name='front_right_wheel_collision'>
        <pose frame=''>0 0 0 0 -0 0</pose>
        <geometry>
          <cylinder>
            <length>0.0453</length>
            <radius>0.075</radius>
          </cylinder>
        </geometry>
      </collision>
      <visual name='front_right_wheel_visual'>
        <pose frame=''>0 0 0 0 -0 0</pose>
        <geometry>
          <mesh>
            <scale>1 1 1</scale>
            <uri>model://sdvun_description/models/sdvun3/meshes/wheel.dae</uri>
          </mesh>
        </geometry>
      </visual>
    </link>
    <joint name='front_right_wheel_joint' type='revolute'>
      <child>front_right_wheel</child>
      <parent>base_link</parent>
      <axis>
        <xyz>9.6e-05 1 9.6e-05</xyz>
        <limit>
          <lower>-1e+16</lower>
          <upper>1e+16</upper>
        </limit>
        <dynamics>
          <spring_reference>0</spring_reference>
          <spring_stiffness>0</spring_stiffness>
        </dynamics>
        <use_parent_model_frame>1</use_parent_model_frame>
      </axis>
    </joint>
    <plugin name='skid_steer_drive_controller' filename='libgazebo_ros_skid_steer_drive.so'>
      <updateRate>100.0</updateRate>
      <robotNamespace>/</robotNamespace>
      <leftFrontJoint>front_left_wheel_joint</leftFrontJoint>
      <rightFrontJoint>front_right_wheel_joint</rightFrontJoint>
      <leftRearJoint>back_left_wheel_joint</leftRearJoint>
      <rightRearJoint>back_right_wheel_joint</rightRearJoint>
      <wheelSeparation>0.4337</wheelSeparation>
      <wheelDiameter>0.150</wheelDiameter>
      <robotBaseFrame>base_link</robotBaseFrame>
      <torque>3</torque>
      <broadcastTF>1</broadcastTF>
      <publishWheelJointState>1</publishWheelJointState>
      <commandTopic>mobile_base/commands/velocity</commandTopic>
      <odometryTopic>odom</odometryTopic>
      <odometryFrame>odom</odometryFrame>
    </plugin>
    <plugin name='joint_state_publisher' filename='libgazebo_ros_joint_state_publisher.so'>
      <jointName>front_left_wheel_joint, front_right_wheel_joint, back_left_wheel_joint, back_right_wheel_joint</jointName>
    </plugin>
    <static>0</static>
    <plugin name='imu_plugin' filename='libgazebo_ros_imu.so'>
      <alwaysOn>1</alwaysOn>
      <topicName>imu</topicName>
      <serviceName>imu_service</serviceName>
      <gaussianNoise>0.0</gaussianNoise>
      <updateRate>200</updateRate>
      <imu>
        <noise>
          <type>gaussian</type>
          <rate>
            <mean>0.0</mean>
            <stddev>2e-4</stddev>
            <bias_mean>0.0000075</bias_mean>
            <bias_stddev>0.0000008</bias_stddev>
          </rate>
          <accel>
            <mean>0.0</mean>
            <stddev>1.7e-2</stddev>
            <bias_mean>0.1</bias_mean>
            <bias_stddev>0.001</bias_stddev>
          </accel>
        </noise>
      </imu>
      <bodyName>base_link</bodyName>
      <frameName>base_link</frameName>
      <xyzOffset>0 0 -0.339436</xyzOffset>
      <rpyOffset>0 -0 0</rpyOffset>
    </plugin>
  </model>
</sdf>
